2023-04-27 10:00:48,810 (__init__.py:1083 MainThread) ERROR - TeleBot: "Threaded polling exception: A request to the Telegram API was unsuccessful. Error code: 409. Description: Conflict: terminated by other getUpdates request; make sure that only one bot instance is running"
2023-04-27 10:00:48,815 (__init__.py:1085 MainThread) ERROR - TeleBot: "Exception traceback:
Traceback (most recent call last):
  File "/usr/local/lib/python3.8/dist-packages/telebot/__init__.py", line 1073, in __threaded_polling
    polling_thread.raise_exceptions()
  File "/usr/local/lib/python3.8/dist-packages/telebot/util.py", line 109, in raise_exceptions
    raise self.exception_info
  File "/usr/local/lib/python3.8/dist-packages/telebot/util.py", line 91, in run
    task(*args, **kwargs)
  File "/usr/local/lib/python3.8/dist-packages/telebot/__init__.py", line 649, in __retrieve_updates
    updates = self.get_updates(offset=(self.last_update_id + 1),
  File "/usr/local/lib/python3.8/dist-packages/telebot/__init__.py", line 623, in get_updates
    json_updates = apihelper.get_updates(self.token, offset, limit, timeout, allowed_updates, long_polling_timeout)
  File "/usr/local/lib/python3.8/dist-packages/telebot/apihelper.py", line 321, in get_updates
    return _make_request(token, method_url, params=payload)
  File "/usr/local/lib/python3.8/dist-packages/telebot/apihelper.py", line 162, in _make_request
    json_result = _check_result(method_name, result)
  File "/usr/local/lib/python3.8/dist-packages/telebot/apihelper.py", line 189, in _check_result
    raise ApiTelegramException(method_name, result, result_json)
telebot.apihelper.ApiTelegramException: A request to the Telegram API was unsuccessful. Error code: 409. Description: Conflict: terminated by other getUpdates request; make sure that only one bot instance is running
"
2023-04-27 10:00:52,620 (__init__.py:1083 MainThread) ERROR - TeleBot: "Threaded polling exception: A request to the Telegram API was unsuccessful. Error code: 409. Description: Conflict: terminated by other getUpdates request; make sure that only one bot instance is running"
2023-04-27 10:00:52,622 (__init__.py:1085 MainThread) ERROR - TeleBot: "Exception traceback:
Traceback (most recent call last):
  File "/usr/local/lib/python3.8/dist-packages/telebot/__init__.py", line 1073, in __threaded_polling
    polling_thread.raise_exceptions()
  File "/usr/local/lib/python3.8/dist-packages/telebot/util.py", line 109, in raise_exceptions
    raise self.exception_info
  File "/usr/local/lib/python3.8/dist-packages/telebot/util.py", line 91, in run
    task(*args, **kwargs)
  File "/usr/local/lib/python3.8/dist-packages/telebot/__init__.py", line 649, in __retrieve_updates
    updates = self.get_updates(offset=(self.last_update_id + 1),
  File "/usr/local/lib/python3.8/dist-packages/telebot/__init__.py", line 623, in get_updates
    json_updates = apihelper.get_updates(self.token, offset, limit, timeout, allowed_updates, long_polling_timeout)
  File "/usr/local/lib/python3.8/dist-packages/telebot/apihelper.py", line 321, in get_updates
    return _make_request(token, method_url, params=payload)
  File "/usr/local/lib/python3.8/dist-packages/telebot/apihelper.py", line 162, in _make_request
    json_result = _check_result(method_name, result)
  File "/usr/local/lib/python3.8/dist-packages/telebot/apihelper.py", line 189, in _check_result
    raise ApiTelegramException(method_name, result, result_json)
telebot.apihelper.ApiTelegramException: A request to the Telegram API was unsuccessful. Error code: 409. Description: Conflict: terminated by other getUpdates request; make sure that only one bot instance is running
"
2023-04-27 10:00:57,192 (__init__.py:1083 MainThread) ERROR - TeleBot: "Threaded polling exception: A request to the Telegram API was unsuccessful. Error code: 409. Description: Conflict: terminated by other getUpdates request; make sure that only one bot instance is running"
2023-04-27 10:00:57,194 (__init__.py:1085 MainThread) ERROR - TeleBot: "Exception traceback:
Traceback (most recent call last):
  File "/usr/local/lib/python3.8/dist-packages/telebot/__init__.py", line 1073, in __threaded_polling
    polling_thread.raise_exceptions()
  File "/usr/local/lib/python3.8/dist-packages/telebot/util.py", line 109, in raise_exceptions
    raise self.exception_info
  File "/usr/local/lib/python3.8/dist-packages/telebot/util.py", line 91, in run
    task(*args, **kwargs)
  File "/usr/local/lib/python3.8/dist-packages/telebot/__init__.py", line 649, in __retrieve_updates
    updates = self.get_updates(offset=(self.last_update_id + 1),
  File "/usr/local/lib/python3.8/dist-packages/telebot/__init__.py", line 623, in get_updates
    json_updates = apihelper.get_updates(self.token, offset, limit, timeout, allowed_updates, long_polling_timeout)
  File "/usr/local/lib/python3.8/dist-packages/telebot/apihelper.py", line 321, in get_updates
    return _make_request(token, method_url, params=payload)
  File "/usr/local/lib/python3.8/dist-packages/telebot/apihelper.py", line 162, in _make_request
    json_result = _check_result(method_name, result)
  File "/usr/local/lib/python3.8/dist-packages/telebot/apihelper.py", line 189, in _check_result
    raise ApiTelegramException(method_name, result, result_json)
telebot.apihelper.ApiTelegramException: A request to the Telegram API was unsuccessful. Error code: 409. Description: Conflict: terminated by other getUpdates request; make sure that only one bot instance is running
"
2023-04-27 10:01:01,504 (__init__.py:1083 MainThread) ERROR - TeleBot: "Threaded polling exception: A request to the Telegram API was unsuccessful. Error code: 409. Description: Conflict: terminated by other getUpdates request; make sure that only one bot instance is running"
2023-04-27 10:01:01,505 (__init__.py:1085 MainThread) ERROR - TeleBot: "Exception traceback:
Traceback (most recent call last):
  File "/usr/local/lib/python3.8/dist-packages/telebot/__init__.py", line 1073, in __threaded_polling
    polling_thread.raise_exceptions()
  File "/usr/local/lib/python3.8/dist-packages/telebot/util.py", line 109, in raise_exceptions
    raise self.exception_info
  File "/usr/local/lib/python3.8/dist-packages/telebot/util.py", line 91, in run
    task(*args, **kwargs)
  File "/usr/local/lib/python3.8/dist-packages/telebot/__init__.py", line 649, in __retrieve_updates
    updates = self.get_updates(offset=(self.last_update_id + 1),
  File "/usr/local/lib/python3.8/dist-packages/telebot/__init__.py", line 623, in get_updates
    json_updates = apihelper.get_updates(self.token, offset, limit, timeout, allowed_updates, long_polling_timeout)
  File "/usr/local/lib/python3.8/dist-packages/telebot/apihelper.py", line 321, in get_updates
    return _make_request(token, method_url, params=payload)
  File "/usr/local/lib/python3.8/dist-packages/telebot/apihelper.py", line 162, in _make_request
    json_result = _check_result(method_name, result)
  File "/usr/local/lib/python3.8/dist-packages/telebot/apihelper.py", line 189, in _check_result
    raise ApiTelegramException(method_name, result, result_json)
telebot.apihelper.ApiTelegramException: A request to the Telegram API was unsuccessful. Error code: 409. Description: Conflict: terminated by other getUpdates request; make sure that only one bot instance is running
"
2023-04-27 10:01:07,051 (__init__.py:1083 MainThread) ERROR - TeleBot: "Threaded polling exception: A request to the Telegram API was unsuccessful. Error code: 409. Description: Conflict: terminated by other getUpdates request; make sure that only one bot instance is running"
2023-04-27 10:01:07,052 (__init__.py:1085 MainThread) ERROR - TeleBot: "Exception traceback:
Traceback (most recent call last):
  File "/usr/local/lib/python3.8/dist-packages/telebot/__init__.py", line 1073, in __threaded_polling
    polling_thread.raise_exceptions()
  File "/usr/local/lib/python3.8/dist-packages/telebot/util.py", line 109, in raise_exceptions
    raise self.exception_info
  File "/usr/local/lib/python3.8/dist-packages/telebot/util.py", line 91, in run
    task(*args, **kwargs)
  File "/usr/local/lib/python3.8/dist-packages/telebot/__init__.py", line 649, in __retrieve_updates
    updates = self.get_updates(offset=(self.last_update_id + 1),
  File "/usr/local/lib/python3.8/dist-packages/telebot/__init__.py", line 623, in get_updates
    json_updates = apihelper.get_updates(self.token, offset, limit, timeout, allowed_updates, long_polling_timeout)
  File "/usr/local/lib/python3.8/dist-packages/telebot/apihelper.py", line 321, in get_updates
    return _make_request(token, method_url, params=payload)
  File "/usr/local/lib/python3.8/dist-packages/telebot/apihelper.py", line 162, in _make_request
    json_result = _check_result(method_name, result)
  File "/usr/local/lib/python3.8/dist-packages/telebot/apihelper.py", line 189, in _check_result
    raise ApiTelegramException(method_name, result, result_json)
telebot.apihelper.ApiTelegramException: A request to the Telegram API was unsuccessful. Error code: 409. Description: Conflict: terminated by other getUpdates request; make sure that only one bot instance is running
"
2023-04-27 10:01:15,121 (__init__.py:1083 MainThread) ERROR - TeleBot: "Threaded polling exception: A request to the Telegram API was unsuccessful. Error code: 409. Description: Conflict: terminated by other getUpdates request; make sure that only one bot instance is running"
2023-04-27 10:01:15,123 (__init__.py:1085 MainThread) ERROR - TeleBot: "Exception traceback:
Traceback (most recent call last):
  File "/usr/local/lib/python3.8/dist-packages/telebot/__init__.py", line 1073, in __threaded_polling
    polling_thread.raise_exceptions()
  File "/usr/local/lib/python3.8/dist-packages/telebot/util.py", line 109, in raise_exceptions
    raise self.exception_info
  File "/usr/local/lib/python3.8/dist-packages/telebot/util.py", line 91, in run
    task(*args, **kwargs)
  File "/usr/local/lib/python3.8/dist-packages/telebot/__init__.py", line 649, in __retrieve_updates
    updates = self.get_updates(offset=(self.last_update_id + 1),
  File "/usr/local/lib/python3.8/dist-packages/telebot/__init__.py", line 623, in get_updates
    json_updates = apihelper.get_updates(self.token, offset, limit, timeout, allowed_updates, long_polling_timeout)
  File "/usr/local/lib/python3.8/dist-packages/telebot/apihelper.py", line 321, in get_updates
    return _make_request(token, method_url, params=payload)
  File "/usr/local/lib/python3.8/dist-packages/telebot/apihelper.py", line 162, in _make_request
    json_result = _check_result(method_name, result)
  File "/usr/local/lib/python3.8/dist-packages/telebot/apihelper.py", line 189, in _check_result
    raise ApiTelegramException(method_name, result, result_json)
telebot.apihelper.ApiTelegramException: A request to the Telegram API was unsuccessful. Error code: 409. Description: Conflict: terminated by other getUpdates request; make sure that only one bot instance is running
"
2023-04-27 10:01:28,199 (__init__.py:1083 MainThread) ERROR - TeleBot: "Threaded polling exception: A request to the Telegram API was unsuccessful. Error code: 409. Description: Conflict: terminated by other getUpdates request; make sure that only one bot instance is running"
2023-04-27 10:01:28,200 (__init__.py:1085 MainThread) ERROR - TeleBot: "Exception traceback:
Traceback (most recent call last):
  File "/usr/local/lib/python3.8/dist-packages/telebot/__init__.py", line 1073, in __threaded_polling
    polling_thread.raise_exceptions()
  File "/usr/local/lib/python3.8/dist-packages/telebot/util.py", line 109, in raise_exceptions
    raise self.exception_info
  File "/usr/local/lib/python3.8/dist-packages/telebot/util.py", line 91, in run
    task(*args, **kwargs)
  File "/usr/local/lib/python3.8/dist-packages/telebot/__init__.py", line 649, in __retrieve_updates
    updates = self.get_updates(offset=(self.last_update_id + 1),
  File "/usr/local/lib/python3.8/dist-packages/telebot/__init__.py", line 623, in get_updates
    json_updates = apihelper.get_updates(self.token, offset, limit, timeout, allowed_updates, long_polling_timeout)
  File "/usr/local/lib/python3.8/dist-packages/telebot/apihelper.py", line 321, in get_updates
    return _make_request(token, method_url, params=payload)
  File "/usr/local/lib/python3.8/dist-packages/telebot/apihelper.py", line 162, in _make_request
    json_result = _check_result(method_name, result)
  File "/usr/local/lib/python3.8/dist-packages/telebot/apihelper.py", line 189, in _check_result
    raise ApiTelegramException(method_name, result, result_json)
telebot.apihelper.ApiTelegramException: A request to the Telegram API was unsuccessful. Error code: 409. Description: Conflict: terminated by other getUpdates request; make sure that only one bot instance is running
"
2023-04-27 10:01:48,276 (__init__.py:1083 MainThread) ERROR - TeleBot: "Threaded polling exception: A request to the Telegram API was unsuccessful. Error code: 409. Description: Conflict: terminated by other getUpdates request; make sure that only one bot instance is running"
2023-04-27 10:01:48,277 (__init__.py:1085 MainThread) ERROR - TeleBot: "Exception traceback:
Traceback (most recent call last):
  File "/usr/local/lib/python3.8/dist-packages/telebot/__init__.py", line 1073, in __threaded_polling
    polling_thread.raise_exceptions()
  File "/usr/local/lib/python3.8/dist-packages/telebot/util.py", line 109, in raise_exceptions
    raise self.exception_info
  File "/usr/local/lib/python3.8/dist-packages/telebot/util.py", line 91, in run
    task(*args, **kwargs)
  File "/usr/local/lib/python3.8/dist-packages/telebot/__init__.py", line 649, in __retrieve_updates
    updates = self.get_updates(offset=(self.last_update_id + 1),
  File "/usr/local/lib/python3.8/dist-packages/telebot/__init__.py", line 623, in get_updates
    json_updates = apihelper.get_updates(self.token, offset, limit, timeout, allowed_updates, long_polling_timeout)
  File "/usr/local/lib/python3.8/dist-packages/telebot/apihelper.py", line 321, in get_updates
    return _make_request(token, method_url, params=payload)
  File "/usr/local/lib/python3.8/dist-packages/telebot/apihelper.py", line 162, in _make_request
    json_result = _check_result(method_name, result)
  File "/usr/local/lib/python3.8/dist-packages/telebot/apihelper.py", line 189, in _check_result
    raise ApiTelegramException(method_name, result, result_json)
telebot.apihelper.ApiTelegramException: A request to the Telegram API was unsuccessful. Error code: 409. Description: Conflict: terminated by other getUpdates request; make sure that only one bot instance is running
"
2023-04-27 10:02:23,619 (__init__.py:1083 MainThread) ERROR - TeleBot: "Threaded polling exception: A request to the Telegram API was unsuccessful. Error code: 409. Description: Conflict: terminated by other getUpdates request; make sure that only one bot instance is running"
2023-04-27 10:02:23,626 (__init__.py:1085 MainThread) ERROR - TeleBot: "Exception traceback:
Traceback (most recent call last):
  File "/usr/local/lib/python3.8/dist-packages/telebot/__init__.py", line 1073, in __threaded_polling
    polling_thread.raise_exceptions()
  File "/usr/local/lib/python3.8/dist-packages/telebot/util.py", line 109, in raise_exceptions
    raise self.exception_info
  File "/usr/local/lib/python3.8/dist-packages/telebot/util.py", line 91, in run
    task(*args, **kwargs)
  File "/usr/local/lib/python3.8/dist-packages/telebot/__init__.py", line 649, in __retrieve_updates
    updates = self.get_updates(offset=(self.last_update_id + 1),
  File "/usr/local/lib/python3.8/dist-packages/telebot/__init__.py", line 623, in get_updates
    json_updates = apihelper.get_updates(self.token, offset, limit, timeout, allowed_updates, long_polling_timeout)
  File "/usr/local/lib/python3.8/dist-packages/telebot/apihelper.py", line 321, in get_updates
    return _make_request(token, method_url, params=payload)
  File "/usr/local/lib/python3.8/dist-packages/telebot/apihelper.py", line 162, in _make_request
    json_result = _check_result(method_name, result)
  File "/usr/local/lib/python3.8/dist-packages/telebot/apihelper.py", line 189, in _check_result
    raise ApiTelegramException(method_name, result, result_json)
telebot.apihelper.ApiTelegramException: A request to the Telegram API was unsuccessful. Error code: 409. Description: Conflict: terminated by other getUpdates request; make sure that only one bot instance is running
"
2023-04-27 10:03:26,981 (__init__.py:1083 MainThread) ERROR - TeleBot: "Threaded polling exception: A request to the Telegram API was unsuccessful. Error code: 409. Description: Conflict: terminated by other getUpdates request; make sure that only one bot instance is running"
2023-04-27 10:03:26,982 (__init__.py:1085 MainThread) ERROR - TeleBot: "Exception traceback:
Traceback (most recent call last):
  File "/usr/local/lib/python3.8/dist-packages/telebot/__init__.py", line 1073, in __threaded_polling
    polling_thread.raise_exceptions()
  File "/usr/local/lib/python3.8/dist-packages/telebot/util.py", line 109, in raise_exceptions
    raise self.exception_info
  File "/usr/local/lib/python3.8/dist-packages/telebot/util.py", line 91, in run
    task(*args, **kwargs)
  File "/usr/local/lib/python3.8/dist-packages/telebot/__init__.py", line 649, in __retrieve_updates
    updates = self.get_updates(offset=(self.last_update_id + 1),
  File "/usr/local/lib/python3.8/dist-packages/telebot/__init__.py", line 623, in get_updates
    json_updates = apihelper.get_updates(self.token, offset, limit, timeout, allowed_updates, long_polling_timeout)
  File "/usr/local/lib/python3.8/dist-packages/telebot/apihelper.py", line 321, in get_updates
    return _make_request(token, method_url, params=payload)
  File "/usr/local/lib/python3.8/dist-packages/telebot/apihelper.py", line 162, in _make_request
    json_result = _check_result(method_name, result)
  File "/usr/local/lib/python3.8/dist-packages/telebot/apihelper.py", line 189, in _check_result
    raise ApiTelegramException(method_name, result, result_json)
telebot.apihelper.ApiTelegramException: A request to the Telegram API was unsuccessful. Error code: 409. Description: Conflict: terminated by other getUpdates request; make sure that only one bot instance is running
"
2023-04-27 10:23:47,400 (__init__.py:960 MainThread) ERROR - TeleBot: "Infinity polling exception: 'result'"
2023-04-27 10:23:47,402 (__init__.py:962 MainThread) ERROR - TeleBot: "Exception traceback:
Traceback (most recent call last):
  File "/usr/local/lib/python3.8/dist-packages/telebot/__init__.py", line 955, in infinity_polling
    self.polling(non_stop=True, timeout=timeout, long_polling_timeout=long_polling_timeout,
  File "/usr/local/lib/python3.8/dist-packages/telebot/__init__.py", line 1043, in polling
    self.__threaded_polling(non_stop=non_stop, interval=interval, timeout=timeout, long_polling_timeout=long_polling_timeout,
  File "/usr/local/lib/python3.8/dist-packages/telebot/__init__.py", line 1118, in __threaded_polling
    raise e
  File "/usr/local/lib/python3.8/dist-packages/telebot/__init__.py", line 1074, in __threaded_polling
    self.worker_pool.raise_exceptions()
  File "/usr/local/lib/python3.8/dist-packages/telebot/util.py", line 148, in raise_exceptions
    raise self.exception_info
  File "/usr/local/lib/python3.8/dist-packages/telebot/util.py", line 91, in run
    task(*args, **kwargs)
  File "/root/Uroboros SMS/pay_crypto.py", line 25, in create_payorder
    url_pay = j['result']['pay_url']
KeyError: 'result'
"
2023-04-27 10:33:13,913 (__init__.py:960 MainThread) ERROR - TeleBot: "Infinity polling exception: 'result'"
2023-04-27 10:33:13,923 (__init__.py:962 MainThread) ERROR - TeleBot: "Exception traceback:
Traceback (most recent call last):
  File "/usr/local/lib/python3.8/dist-packages/telebot/__init__.py", line 955, in infinity_polling
    self.polling(non_stop=True, timeout=timeout, long_polling_timeout=long_polling_timeout,
  File "/usr/local/lib/python3.8/dist-packages/telebot/__init__.py", line 1043, in polling
    self.__threaded_polling(non_stop=non_stop, interval=interval, timeout=timeout, long_polling_timeout=long_polling_timeout,
  File "/usr/local/lib/python3.8/dist-packages/telebot/__init__.py", line 1118, in __threaded_polling
    raise e
  File "/usr/local/lib/python3.8/dist-packages/telebot/__init__.py", line 1074, in __threaded_polling
    self.worker_pool.raise_exceptions()
  File "/usr/local/lib/python3.8/dist-packages/telebot/util.py", line 148, in raise_exceptions
    raise self.exception_info
  File "/usr/local/lib/python3.8/dist-packages/telebot/util.py", line 91, in run
    task(*args, **kwargs)
  File "/root/Uroboros SMS/pay_crypto.py", line 25, in create_payorder
    url_pay = j['result']['pay_url']
KeyError: 'result'
"
2023-04-27 10:34:17,595 (__init__.py:960 MainThread) ERROR - TeleBot: "Infinity polling exception: 'tzid'"
2023-04-27 10:34:17,597 (__init__.py:962 MainThread) ERROR - TeleBot: "Exception traceback:
Traceback (most recent call last):
  File "/usr/local/lib/python3.8/dist-packages/telebot/__init__.py", line 955, in infinity_polling
    self.polling(non_stop=True, timeout=timeout, long_polling_timeout=long_polling_timeout,
  File "/usr/local/lib/python3.8/dist-packages/telebot/__init__.py", line 1043, in polling
    self.__threaded_polling(non_stop=non_stop, interval=interval, timeout=timeout, long_polling_timeout=long_polling_timeout,
  File "/usr/local/lib/python3.8/dist-packages/telebot/__init__.py", line 1118, in __threaded_polling
    raise e
  File "/usr/local/lib/python3.8/dist-packages/telebot/__init__.py", line 1074, in __threaded_polling
    self.worker_pool.raise_exceptions()
  File "/usr/local/lib/python3.8/dist-packages/telebot/util.py", line 148, in raise_exceptions
    raise self.exception_info
  File "/usr/local/lib/python3.8/dist-packages/telebot/util.py", line 91, in run
    task(*args, **kwargs)
  File "/usr/local/lib/python3.8/dist-packages/telebot/__init__.py", line 6428, in _run_middlewares_and_handler
    result = handler['function'](message)
  File "/root/Uroboros SMS/sms.py", line 254, in call_back
    idtz_idtrans = str(j['tzid']) + '-' + str(call.from_user.id)  #id \u0437\u0430\u043a\u0430\u0437\u0430 \u0438 \u0442\u0440\u0430\u043d\u0437\u044b
KeyError: 'tzid'
"
2023-04-27 13:07:46,938 (__init__.py:960 MainThread) ERROR - TeleBot: "Infinity polling exception: 'tzid'"
2023-04-27 13:07:46,940 (__init__.py:962 MainThread) ERROR - TeleBot: "Exception traceback:
Traceback (most recent call last):
  File "/usr/local/lib/python3.8/dist-packages/telebot/__init__.py", line 955, in infinity_polling
    self.polling(non_stop=True, timeout=timeout, long_polling_timeout=long_polling_timeout,
  File "/usr/local/lib/python3.8/dist-packages/telebot/__init__.py", line 1043, in polling
    self.__threaded_polling(non_stop=non_stop, interval=interval, timeout=timeout, long_polling_timeout=long_polling_timeout,
  File "/usr/local/lib/python3.8/dist-packages/telebot/__init__.py", line 1118, in __threaded_polling
    raise e
  File "/usr/local/lib/python3.8/dist-packages/telebot/__init__.py", line 1074, in __threaded_polling
    self.worker_pool.raise_exceptions()
  File "/usr/local/lib/python3.8/dist-packages/telebot/util.py", line 148, in raise_exceptions
    raise self.exception_info
  File "/usr/local/lib/python3.8/dist-packages/telebot/util.py", line 91, in run
    task(*args, **kwargs)
  File "/usr/local/lib/python3.8/dist-packages/telebot/__init__.py", line 6428, in _run_middlewares_and_handler
    result = handler['function'](message)
  File "/root/Uroboros SMS/sms.py", line 254, in call_back
    idtz_idtrans = str(j['tzid']) + '-' + str(call.from_user.id)  #id \u0437\u0430\u043a\u0430\u0437\u0430 \u0438 \u0442\u0440\u0430\u043d\u0437\u044b
KeyError: 'tzid'
"
